Workbook
Name base_year: Assumptions!$B$7
Name beta: Assumptions!$B$25
Name beta_2y_blume: Assumptions!$B$54
Name beta_2y_raw: Assumptions!$B$53
Name beta_5y_blume: Assumptions!$B$52
Name beta_5y_raw: Assumptions!$B$51
Name beta_operating: WACC!$B$24
Name beta_regression_crosscheck: Assumptions!$B$26
Name capex_pct: Assumptions!$B$21
Name capex_pct_rev: Assumptions!$B$21
Name cash: Assumptions!$B$11
Name company: Assumptions!$B$4
Name comps: Assumptions!$B$41
Name comps_med: Comps!$B$13
Name comps_med_ex_ifrs: Comps!$B$29
Name comps_q1: Comps!$B$12
Name comps_q3: Comps!$B$14
Name cost_debt_pretax: Assumptions!$B$29
Name cost_equity: Assumptions!$B$28
Name cross_check_flags: DCF!$B$67
Name da_pct: Assumptions!$B$20
Name da_pct_rev: Assumptions!$B$20
Name debt: Assumptions!$B$12
Name deck_ev_ebitda: Comps!$B$28
Name deck_ev_ebitda_10y_median_gurufocus: Comps!$B$33
Name deck_ev_ebitda_gurufocus: Comps!$B$32
Name deck_ev_ebitda_stockanalysis: Comps!$B$31
Name ebit_margin: Assumptions!$B$19
Name erp: Assumptions!$B$27
Name ev_exit: DCF!$C$30
Name ev_perp: DCF!$B$30
Name exit_mult: Assumptions!$B$33
Name exit_multiple_ev_ebitda: Assumptions!$B$33
Name ff_base_dcf: Comps!$B$44
Name ff_comps_hi: Comps!$C$40
Name ff_comps_lo: Comps!$B$40
Name ff_dcf_exit_hi: Comps!$C$38
Name ff_dcf_exit_lo: Comps!$B$38
Name ff_dcf_perp_hi: Comps!$C$37
Name ff_dcf_perp_lo: Comps!$B$37
Name ff_mc_hi: Comps!$C$39
Name ff_mc_lo: Comps!$B$39
Name ff_price: Comps!$B$45
Name ff_pt_hi: Comps!$C$41
Name ff_pt_lo: Comps!$B$41
Name ff_w52_hi: Comps!$C$42
Name ff_w52_lo: Comps!$B$42
Name fye: Assumptions!$B$6
Name g_exit_at_ronic: DCF!$B$48
Name g_fy27: Assumptions!$B$14
Name g_fy28: Assumptions!$B$15
Name g_fy29: Assumptions!$B$16
Name g_fy30: Assumptions!$B$17
Name g_fy31: Assumptions!$B$18
Name implied_ev_fy27_ebitda: DCF!$B$66
Name implied_ev_ltm_ebitda: DCF!$B$65
Name implied_margin: DCF!$B$43
Name implied_margin_probe_hi: Assumptions!$B$46
Name implied_margin_probe_lo: Assumptions!$B$45
Name integrity_summary: DCF!$D$57

Sheet Cover
A1: Deckers Outdoor Corporation (DECK): DCF valuation
A3: Company | B3: =company -> Deckers Outdoor Corp
A4: Ticker | B4: =ticker -> DECK
A5: Base fiscal year | B5: =base_year -> FY2026
A6: Price date | B6: =price_date -> 2026-09-21
A7: Current share price ($) | B7: =price -> 80.23
A8: Diluted shares (count) | B8: =shares -> 136710227
A9: WACC (live formula, WACC tab) | B9: =wacc_calc -> 0.0923
A10: Implied price, perpetuity method ($) | B10: =price_perp -> 130.74592
A11: Implied price, exit multiple method ($) | B11: =price_exit -> 117.15193
A12: Upside, perpetuity | B12: =upside_perp -> 0.62963879
A13: Upside, exit multiple | B13: =upside_exit -> 0.46020101
A14: Integrity checks | B14: =integrity_summary -> 6 of 6 pass
A15: Cross-checks outside reference range | B15: =cross_check_flags -> 1 outside range: Implied g from exit multiple (timed to exit convention)
A17: Color key: blue = hardcoded input (Assumptions / Historical / Comps inputs), black = same-sheet formula, green = cross-sheet link.
A18: Units: $ thousands throughout except price per share ($) and share counts (count).

Sheet Assumptions
A1: Assumptions: all rows from inputs/assumptions.csv (blue = hardcoded input)
A3: key | B3: value | C3: unit | D3: source | E3: status
A4: company | B4: Deckers Outdoor Corp | C4: text | D4: 10-K | E4: input
A5: ticker | B5: DECK | C5: text | D5: NYSE | E5: input
A6: fye | B6: 03-31 | C6: date | D6: 10-K | E6: input
A7: base_year | B7: FY2026 | C7: text | D7: 10-K | E7: input
A8: price | B8: 80.23 | C8: USD | D8: close 2026-09-21 Google Finance | E8: input
A9: price_date | B9: 2026-09-21 | C9: date | D9: Google Finance | E9: input
A10: shares_diluted_current | B10: 136710227 | C10: shares | D10: 10-Q cover 136,414,227 basic as of 2026-07-09 + 296K dilutive effect of equity awards, 10-Q Note 9 | E10: input
A11: cash | B11: 1570421 | C11: USD thousands | D11: 10-Q Q1 FY27 balance sheet 1,602,589 at 2026-06-30 less 32,168 repurchased through 2026-07-09 per 10-Q subsequent events, to match the Jul 9 share count | E11: input
A12: debt | B12: 0 | C12: USD thousands | D12: 10-K | E12: input
A13: lease_liabilities_total | B13: 375194 | C13: USD thousands | D13: 10-K FY2026 | E13: excluded from bridge (lease cost in EBIT)
A14: rev_growth_fy27 | B14: 0.075 | C14: pct | D14: FY27 guide midpoint 5.885B / FY26 net sales 5,472,296 | E14: input
A15: rev_growth_fy28 | B15: 0.07 | C15: pct | D15: decay | E15: input
A16: rev_growth_fy29 | B16: 0.06 | C16: pct | D16: decay | E16: input
A17: rev_growth_fy30 | B17: 0.05 | C17: pct | D17: decay | E17: input
A18: rev_growth_fy31 | B18: 0.04 | C18: pct | D18: decay | E18: input
A19: ebit_margin | B19: 0.215 | C19: pct | D19: FY27 guidance ~21.5% | E19: input
A20: da_pct_rev | B20: 0.014 | C20: pct | D20: FY26 10-K cash flow: Depreciation, amortization, and accretion 75,773 / Net sales 5,472,296 = 1.38% | E20: input
A21: capex_pct_rev | B21: 0.015 | C21: pct | D21: FY26 10-K cash flow: Purchases of property and equipment 84,623 / Net sales 5,472,296 = 1.55% | E21: input
... A25: beta | B25: 1 | C25: x | D25: Damodaran Shoe Jan 2026 cash-corrected unlevered; DECK ~0 debt | E25: input
A26: beta_regression_crosscheck | B26: =beta_5y_raw -> 1.0988 | C26: x | D26: yfinance DECK vs SPY 5Y monthly raw, Blume 1.0662, R2 0.19, inputs/beta.csv | E26: formula
A27: erp | B27: 0.0423 | C27: pct | D27: Damodaran implied ERP start-2026; Sept 2026 not published | E27: input
A28: cost_equity | B28: =WACC!B11 -> 0.0923 | C28: pct | D28: CAPM | E28: formula
A29: cost_debt_pretax | B29: 0.056 | C29: pct | D29: 5.60% used; synthetic AAA estimate 5.40% (Rf 5.00% + 0.40% spread, Damodaran Jan 2026); zero weight in WACC because debt = 0 | E29: input
A30: weight_equity | B30: =WACC!B20 -> 1 | C30: pct | D30: no debt | E30: formula
A31: wacc | B31: =WACC!B22 -> 0.0923 | C31: pct | D31: formula: = cost_equity x weight_equity; debt weight 0 | E31: formula
A32: terminal_growth | B32: 0.025 | C32: pct | D32: below nominal GDP and Rf | E32: input
A33: exit_multiple_ev_ebitda | B33: 9.5 | C33: x | D33: below 13.49x 10Y median above 7.62x current | E33: input
A34: mc_runs | B34: 10000 | C34: n | D34: practitioner standard | E34: input
A35: mc_seed | B35: 42 | C35: n | D35: reproducibility | E35: input
A36: mc_growth_tri | B36: 3,6,9 | C36: pct | D36: mode 6% = average of the FY27 to FY31 growth path; range +/-3pp | E36: input
A37: mc_margin_tri | B37: 18,21.5,24 | C37: pct | D37: floor 18% = FY22 17.9% and FY23 18.0% EBIT margin trough, Historical!B28:C28; mode 21.5% = FY27 guide; cap 24% just above FY25 23.6% peak | E37: input
A38: mc_wacc_normal | B38: 9.23,0.5 | C38: pct | D38: centered on base WACC | E38: input
A39: mc_g_tri | B39: 1.5,2.5,3.0 | C39: pct | D39: mode = base terminal g 2.5%; max 3.0%, below nominal GDP and Rf; min 1.5% | E39: input
A40: mc_guardrail_wacc_minus_g_min | B40: 0.015 | C40: pct | D40: floor on WACC minus g | E40: input
A41: comps | B41: CROX,NKE,ONON,BIRK,SHOO,WWW | C41: tickers | D41: CROX stockanalysis.com / GuruFocus; NKE, ONON, BIRK, SHOO stockanalysis.com; WWW GuruFocus; retrieved Sep 2026 | E41: input
A42: sens_wacc_step | B42: 0.005 | C42: pct | D42: sensitivity grid step | E42: input
A43: sens_g_step | B43: 0.005 | C43: pct | D43: sensitivity grid step | E43: input
A44: sens_mult_step | B44: 0.5 | C44: x | D44: sensitivity grid step | E44: input
...

Sheet Historical
A1: Historical: fs_value from inputs/historicals.csv, $ thousands (shares in thousands); blue = input, blank = not in source
A3: Line item | B3: FY2022 | C3: FY2023 | D3: FY2024 | E3: FY2025 | F3: FY2026 | G3: source_file(s) | H3: note
A4: Net sales | B4: 3150339 | C4: 3627286 | D4: 4287763 | E4: 4985612 | F4: 5472296 | G4: 10-K FY2024 (FY22-23), 10-K FY2026 (FY24-26), Consolidated Statements of Comprehensive Income
A5: Cost of sales | B5: 1542788 | C5: 1801916 | D5: 1902275 | E5: 2099949 | F5: 2314570 | G5: 10-K FY2024 (FY22-23), 10-K FY2026 (FY24-26), Consolidated Statements of Comprehensive Income
A6: Gross profit | B6: 1607551 | C6: 1825370 | D6: 2385488 | E6: 2885663 | F6: 3157726 | G6: 10-K FY2024 (FY22-23), 10-K FY2026 (FY24-26), Consolidated Statements of Comprehensive Income
A7: SG&A | B7: 1042844 | C7: 1172619 | D7: 1457974 | E7: 1706571 | F7: 1894823 | G7: 10-K FY2024 (FY22-23), 10-K FY2026 (FY24-26), Consolidated Statements of Comprehensive Income
A8: Income from operations | B8: 564707 | C8: 652751 | D8: 927514 | E8: 1179092 | F8: 1262903 | G8: 10-K FY2024 (FY22-23), 10-K FY2026 (FY24-26), Consolidated Statements of Comprehensive Income
A9: Total other income net | B9: 69 | C9: -13331 | D9: -51427 | E9: -64207 | F9: -63453 | G9: 10-K FY2024 (FY22-23), 10-K FY2026 (FY24-26), Consolidated Statements of Comprehensive Income | H9: as printed: negative = net other income, added to operating income
A10: Income before income taxes | B10: 564638 | C10: 666082 | D10: 978941 | E10: 1243299 | F10: 1326356 | G10: 10-K FY2024 (FY22-23), 10-K FY2026 (FY24-26), Consolidated Statements of Comprehensive Income
A11: Income tax expense | B11: 112689 | C11: 149260 | D11: 219378 | E11: 277208 | F11: 302285 | G11: 10-K FY2024 (FY22-23), 10-K FY2026 (FY24-26), Consolidated Statements of Comprehensive Income
A12: Net income | B12: 451949 | C12: 516822 | D12: 759563 | E12: 966091 | F12: 1024071 | G12: 10-K FY2024 (FY22-23), 10-K FY2026 (FY24-26), Consolidated Statements of Comprehensive Income
A13: Depreciation amortization and accretion | B13: 42878 | C13: 47858 | D13: 57587 | E13: 69353 | F13: 75773 | G13: 10-K FY2024 (FY22-23), 10-K FY2026 (FY24-26), Consolidated Statements of Cash Flows
A14: Stock-based compensation | B14: 26816 | C14: 26897 | D14: 37288 | E14: 37943 | F14: 44835 | G14: 10-K FY2024 (FY22-23), 10-K FY2026 (FY24-26), Consolidated Statements of Cash Flows
A15: Purchases of property and equipment | B15: -51017 | C15: -81025 | D15: -89365 | E15: -86171 | F15: -84623 | G15: 10-K FY2024 (FY22-23), 10-K FY2026 (FY24-26), Consolidated Statements of Cash Flows | H15: as printed in cash-flow statement: negative = cash outflow
A16: Cash and cash equivalents | C16: 981795 | D16: 1502051 | E16: 1889188 | F16: 1907249 | G16: 10-K FY2024 (FY23-24), 10-K FY2026 (FY25-26), Consolidated Balance Sheets
A17: Trade accounts receivable net | C17: 301511 | D17: 296565 | E17: 332872 | F17: 318978 | G17: 10-K FY2024 (FY23-24), 10-K FY2026 (FY25-26), Consolidated Balance Sheets
A18: Inventories | C18: 532852 | D18: 474311 | E18: 495226 | F18: 487018 | G18: 10-K FY2024 (FY23-24), 10-K FY2026 (FY25-26), Consolidated Balance Sheets
A19: Trade accounts payable | C19: 265605 | D19: 378503 | E19: 417955 | F19: 384529 | G19: 10-K FY2024 (FY23-24), 10-K FY2026 (FY25-26), Consolidated Balance Sheets
A20: Operating lease liabilities current | C20: 50765 | D20: 53581 | E20: 54453 | F20: 83931 | G20: 10-K FY2024 (FY23-24), 10-K FY2026 (FY25-26), Consolidated Balance Sheets
A21: Long-term operating lease liabilities | C21: 195723 | D21: 213298 | E21: 222522 | F21: 291263 | G21: 10-K FY2024 (FY23-24), 10-K FY2026 (FY25-26), Consolidated Balance Sheets
A22: Total stockholders' equity | E22: 2513013 | F22: 2499638 | G22: 10-K FY2026, Consolidated Balance Sheets | H22: FY2025: 10-K FY2026, Consolidated Balance Sheets (line 1368); FY2026: 10-K FY2026, Consolidated Balance Sheets (line 1368)
A23: Long-term debt | G23: 10-K FY2024 (FY23-24), 10-K FY2026 (FY25-26), Consolidated Balance Sheets | H23: no debt line item on DECK balance sheet; undrawn revolver only
A24: Diluted weighted-average shares | B24: 166734 | C24: 160116 | D24: 156285 | E24: 152670 | F24: 145805 | G24: 10-K FY2024 (FY22-23), 10-K FY2026 (FY24-26), Note: Basic and Diluted Shares | H24: FY2022: restated x6 post-split; FY2023: fs_value restated x6 post-split; xbrl_value already post-split as filed (FY2025 10-K)
A25: Ratios (formulas)
A26: Revenue growth | C26: =IF(COUNT(B4,C4)=2,C4/B4-1,"") -> 0.15139545 | D26: =IF(COUNT(C4,D4)=2,D4/C4-1,"") -> 0.18208572 | E26: =IF(COUNT(D4,E4)=2,E4/D4-1,"") -> 0.16275363 | F26: =IF(COUNT(E4,F4)=2,F4/E4-1,"") -> 0.097617705
A27: Gross margin | B27: =IF(COUNT(B6,B4)=2,B6/B4,"") -> 0.51027874 | C27: =IF(COUNT(C6,C4)=2,C6/C4,"") -> 0.503233 | D27: =IF(COUNT(D6,D4)=2,D6/D4,"") -> 0.55634791 | E27: =IF(COUNT(E6,E4)=2,E6/E4,"") -> 0.57879815 | F27: =IF(COUNT(F6,F4)=2,F6/F4,"") -> 0.5770386
A28: EBIT margin (income from operations / revenue) | B28: =IF(COUNT(B8,B4)=2,B8/B4,"") -> 0.17925277 | C28: =IF(COUNT(C8,C4)=2,C8/C4,"") -> 0.17995576 | D28: =IF(COUNT(D8,D4)=2,D8/D4,"") -> 0.21631653 | E28: =IF(COUNT(E8,E4)=2,E8/E4,"") -> 0.23649895 | F28: =IF(COUNT(F8,F4)=2,F8/F4,"") -> 0.23078119
A29: D&A % revenue | B29: =IF(COUNT(B13,B4)=2,B13/B4,"") -> 0.013610599 | C29: =IF(COUNT(C13,C4)=2,C13/C4,"") -> 0.013193887 | D29: =IF(COUNT(D13,D4)=2,D13/D4,"") -> 0.013430546 | E29: =IF(COUNT(E13,E4)=2,E13/E4,"") -> 0.013910629 | F29: =IF(COUNT(F13,F4)=2,F13/F4,"") -> 0.013846656
A30: Capex % revenue (ABS of cash-flow line) | B30: =IF(COUNT(B15,B4)=2,ABS(B15)/B4,"") -> 0.01619413 | C30: =IF(COUNT(C15,C4)=2,ABS(C15)/C4,"") -> 0.022337638 | D30: =IF(COUNT(D15,D4)=2,ABS(D15)/D4,"") -> 0.02084187 | E30: =IF(COUNT(E15,E4)=2,ABS(E15)/E4,"") -> 0.017283936 | F30: =IF(COUNT(F15,F4)=2,ABS(F15)/F4,"") -> 0.015463893
A31: NWC = AR + Inventories - AP ($ thousands) | B31: =IF(COUNT(B17,B18,B19)=3,B17+B18-B19,"") | C31: =IF(COUNT(C17,C18,C19)=3,C17+C18-C19,"") -> 568758 | D31: =IF(COUNT(D17,D18,D19)=3,D17+D18-D19,"") -> 392373 | E31: =IF(COUNT(E17,E18,E19)=3,E17+E18-E19,"") -> 410143 | F31: =IF(COUNT(F17,F18,F19)=3,F17+F18-F19,"") -> 421467
A32: NWC % revenue | B32: =IF(AND(ISNUMBER(B31),ISNUMBER(B4)),B31/B4,"") | C32: =IF(AND(ISNUMBER(C31),ISNUMBER(C4)),C31/C4,"") -> 0.15679988 | D32: =IF(AND(ISNUMBER(D31),ISNUMBER(D4)),D31/D4,"") -> 0.091509955 | E32: =IF(AND(ISNUMBER(E31),ISNUMBER(E4)),E31/E4,"") -> 0.082265327 | F32: =IF(AND(ISNUMBER(F31),ISNUMBER(F4)),F31/F4,"") -> 0.077018312
A33: Effective tax rate | B33: =IF(COUNT(B11,B10)=2,B11/B10,"") -> 0.19957743 | C33: =IF(COUNT(C11,C10)=2,C11/C10,"") -> 0.22408652 | D33: =IF(COUNT(D11,D10)=2,D11/D10,"") -> 0.22409726 | E33: =IF(COUNT(E11,E10)=2,E11/E10,"") -> 0.22296165 | F33: =IF(COUNT(F11,F10)=2,F11/F10,"") -> 0.22790638
A34: SBC % revenue | B34: =IF(COUNT(B14,B4)=2,B14/B4,"") -> 0.0085120998 | C34: =IF(COUNT(C14,C4)=2,C14/C4,"") -> 0.0074151859 | D34: =IF(COUNT(D14,D4)=2,D14/D4,"") -> 0.0086963762 | E34: =IF(COUNT(E14,E4)=2,E14/E4,"") -> 0.0076105 | F34: =IF(COUNT(F14,F4)=2,F14/F4,"") -> 0.0081930875
A35: ROIC FY26 = income from operations x (1 - tax) / (equity - cash + operating lease liabilities, current + long-term) | F35: =F8*(1-tax)/(F22-F16+F20+F21) -> 1.0050149
A36: ROIC FY26 excluding leases = same numerator / (equity - cash) | F36: =F8*(1-tax)/(F22-F16) -> 1.6415486
A38: LTM to Jun 30 2026 ($ thousands): FY2026 + Q1 FY2027 - Q1 FY2026
A39: Line item | B39: FY2026 | C39: Q1 FY2027 | D39: Q1 FY2026 | E39: LTM Jun 2026 | G39: source_file(s) | H39: note
A40: Income from operations | B40: =F8 -> 1262903 | C40: 155301 | D40: 165287 | E40: =B40+C40-D40 -> 1252917 | G40: 10-K FY2026 (FY2026 column); 10-Q Q1 FY2027 condensed statements, current-period column (Q1 FY2027) and prior-period column (Q1 FY2026) | H40: inputs/historicals.csv period LTM_Jun26 fs_value 1,252,917 (LTM to 2026-06-30 = FY2026 + Q1 FY2027 - Q1 FY2026); must equal column E
A41: Depreciation amortization and accretion | B41: =F13 -> 75773 | C41: 17713 | D41: 19424 | E41: =B41+C41-D41 -> 74062 | G41: 10-K FY2026 (FY2026 column); 10-Q Q1 FY2027 condensed statements, current-period column (Q1 FY2027) and prior-period column (Q1 FY2026) | H41: inputs/historicals.csv period LTM_Jun26 fs_value 74,062 (LTM to 2026-06-30 = FY2026 + Q1 FY2027 - Q1 FY2026); must equal column E
A42: LTM EBITDA = income from operations + D&A and accretion | B42: =B40+B41 -> 1338676 | C42: =C40+C41 -> 173014 | D42: =D40+D41 -> 184711 | E42: =E40+E41 -> 1326979 | G42: formula; feeds Comps tab (defined name ltm_ebitda)

Sheet WACC
A1: WACC: every cell is a formula or a green link; no typed numbers on this sheet
A3: Component | B3: Value | C3: Formula / source
A4: Risk-free rate (rf) | B4: =rf -> 0.05 | C4: Assumptions!rf
A5: Beta: Damodaran shoe, cash-corrected (operating) unlevered (used) | B5: =beta -> 1 | C5: Assumptions!beta; cash-corrected, so compare with the operating beta rows below
A6: Beta: regression 5Y monthly, raw (includes cash drag, not cash-corrected) | B6: =beta_5y_raw -> 1.0988 | C6: Assumptions!beta_5y_raw (inputs/beta.csv)
A7: Beta: regression 5Y monthly, Blume (0.67*raw+0.33) | B7: =beta_5y_blume -> 1.0662 | C7: Assumptions!beta_5y_blume
A8: Beta: regression 2Y weekly, raw | B8: =beta_2y_raw -> 1.3346 | C8: Assumptions!beta_2y_raw
A9: Beta: regression 2Y weekly, Blume | B9: =beta_2y_blume -> 1.2242 | C9: Assumptions!beta_2y_blume
A10: Equity risk premium (ERP) | B10: =erp -> 0.0423 | C10: Assumptions!erp
A11: Cost of equity Ke = rf + beta × ERP | B11: =B4+B5*B10 -> 0.0923 | C11: CAPM
A12: Pre-tax cost of debt (Kd) | B12: =kd_pretax -> 0.056 | C12: Assumptions!cost_debt_pretax
A13: Tax rate (t) | B13: =tax -> 0.23 | C13: Assumptions!tax_rate
A14: After-tax cost of debt Kd × (1 − t) | B14: =B12*(1-B13) -> 0.04312
A15: Share price ($) | B15: =price -> 80.23 | C15: Assumptions!price
A16: Diluted shares (count) | B16: =shares -> 136710227 | C16: Assumptions!shares_diluted_current
A17: Market cap ($ thousands) = price × shares / 1000 | B17: =B15*B16/1000 -> 10968262
A18: Debt ($ thousands) | B18: =debt -> 0 | C18: Assumptions!debt
A19: Total capital ($ thousands) | B19: =B17+B18 -> 10968262
A20: Equity weight We | B20: =B17/B19 -> 1
A21: Debt weight Wd | B21: =B18/B19 -> 0
A22: WACC = Ke×We + Kd×(1−t)×Wd (used; feeds DCF) | B22: =B11*B20+B14*B21 -> 0.0923 | C22: defined name: wacc_calc
A23: WACC at 5Y regression equity beta (includes cash drag, not comparable to the cash-corrected beta; see row 24) | B23: =(B4+B6*B10)*B20+B14*B21 -> 0.09647924 | C23: not used downstream
A24: Operating beta equivalent of the 5Y regression beta_5y_raw / (1 − cash / market cap) | B24: =B6/(1-cash/B17) -> 1.2824144 | C24: cash drag removed, so it compares like for like with the cash-corrected Damodaran beta
A25: Ke at operating beta rf + beta_op × ERP | B25: =B4+B24*B10 -> 0.10424613
A26: WACC at operating beta Ke_op × We + Kd × (1 − t) × Wd | B26: =B25*B20+B14*B21 -> 0.10424613 | C26: equals Ke_op because Wd = 0
A27: Value per share at that Ke ($, perpetuity method) | B27: =(SUMPRODUCT(DCF!$C$13:$G$13,1/(1+$B$26)^DCF!$C$21:$G$21)+DCF!$G$13*(1+tg)/($B$26-tg)/(1+$B$26)^DCF!$G$21+cash-debt)/shares*1000 -> 113.06915 | C27: same repricing as Sensitivity grid 1 with the operating-beta WACC swapped in

Sheet DCF
A1: DCF: unlevered FCFF, mid-year convention, $ thousands (price in $/share). Every numeric cell is a formula or a link; labels, notes and check ranges are text.
A2: ($ thousands) | B2: FY2026A | C2: FY2027E | D2: FY2028E | E2: FY2029E | F2: FY2030E | G2: FY2031E | H2: Notes
A3: Revenue growth | B3: =Historical!F26 -> 0.097617705 | C3: =g_fy27 -> 0.075 | D3: =g_fy28 -> 0.07 | E3: =g_fy29 -> 0.06 | F3: =g_fy30 -> 0.05 | G3: =g_fy31 -> 0.04 | H3: FY26A growth from Historical; FY27 to FY31 from Assumptions g_fy27..g_fy31
A4: Revenue | B4: =Historical!F4 -> 5472296 | C4: =B4*(1+C3) -> 5882718.2 | D4: =C4*(1+D3) -> 6294508.5 | E4: =D4*(1+E3) -> 6672179 | F4: =E4*(1+F3) -> 7005787.9 | G4: =F4*(1+G3) -> 7286019.4
A5: EBIT margin | B5: =B6/B4 -> 0.23078119 | C5: =ebit_margin -> 0.215 | D5: =ebit_margin -> 0.215 | E5: =ebit_margin -> 0.215 | F5: =ebit_margin -> 0.215 | G5: =ebit_margin -> 0.215 | H5: FY26A actual; forecast = Assumptions ebit_margin (flat)
A6: EBIT | B6: =Historical!F8 -> 1262903 | C6: =C4*C5 -> 1264784.4 | D6: =D4*D5 -> 1353319.3 | E6: =E4*E5 -> 1434518.5 | F6: =F4*F5 -> 1506244.4 | G6: =G4*G5 -> 1566494.2
A7: Taxes on EBIT (EBIT × tax) | C7: =C6*tax -> 290900.41 | D7: =D6*tax -> 311263.44 | E7: =E6*tax -> 329939.25 | F7: =F6*tax -> 346436.21 | G7: =G6*tax -> 360293.66
A8: NOPAT | C8: =C6-C7 -> 973884 | D8: =D6-D7 -> 1042055.9 | E8: =E6-E7 -> 1104579.2 | F8: =F6-F7 -> 1159808.2 | G8: =G6-G7 -> 1206200.5
A9: + D&A | B9: =Historical!F13 -> 75773 | C9: =da_pct*C4 -> 82358.055 | D9: =da_pct*D4 -> 88123.119 | E9: =da_pct*E4 -> 93410.506 | F9: =da_pct*F4 -> 98081.031 | G9: =da_pct*G4 -> 102004.27
A10: − Capex | B10: =ABS(Historical!F15) -> 84623 | C10: =capex_pct*C4 -> 88240.773 | D10: =capex_pct*D4 -> 94417.627 | E10: =capex_pct*E4 -> 100082.68 | F10: =capex_pct*F4 -> 105086.82 | G10: =capex_pct*G4 -> 109290.29 | H10: Historical capex line is negative in the cash-flow statement; shown here as a positive outflow
A11: NWC level (AR + Inv − AP) | B11: =Historical!F31 -> 421467 | C11: =nwc_pct*C4 -> 452969.3 | D11: =nwc_pct*D4 -> 484677.15 | E11: =nwc_pct*E4 -> 513757.78 | F11: =nwc_pct*F4 -> 539445.67 | G11: =nwc_pct*G4 -> 561023.5 | H11: FY26A = actual AR+Inv−AP from Historical; forecast = nwc_pct × revenue
A12: − Change in NWC (increase = outflow) | C12: =C11-B11 -> 31502.301 | D12: =D11-C11 -> 31707.851 | E12: =E11-D11 -> 29080.629 | F12: =F11-E11 -> 25687.889 | G12: =G11-F11 -> 21577.827
A13: FCFF = NOPAT + D&A − Capex − ΔNWC | C13: =C8+C9-C10-C12 -> 936498.98 | D13: =D8+D9-D10-D12 -> 1004053.5 | E13: =E8+E9-E10-E12 -> 1068826.4 | F13: =F8+F9-F10-F12 -> 1127114.5 | G13: =G8+G9-G10-G12 -> 1177336.7
A14: EBITDA (EBIT + D&A) | B14: =B6+B9 -> 1338676 | C14: =C6+C9 -> 1347142.5 | D14: =D6+D9 -> 1441442.4 | E14: =E6+E9 -> 1527929 | F14: =F6+F9 -> 1604325.4 | G14: =G6+G9 -> 1668498.5
A16: SBC: expense stays inside EBIT and is not added back to FCFF (SBC treated as a cost). Existing unvested awards are captured in the share count via the 296K dilutive effect (10-Q Note 9).
A17: Leases: operating lease cost stays inside EBIT. No operating lease liability is deducted in the equity bridge (leases excluded from the bridge because lease cost is already in EBIT).
A19: Fiscal year (numeric, from header) | B19: =VALUE(MID(B$2,3,4)) -> 2026 | C19: =VALUE(MID(C$2,3,4)) -> 2027 | D19: =VALUE(MID(D$2,3,4)) -> 2028 | E19: =VALUE(MID(E$2,3,4)) -> 2029 | F19: =VALUE(MID(F$2,3,4)) -> 2030 | G19: =VALUE(MID(G$2,3,4)) -> 2031
A20: Year offset n (FY − base FY) | B20: =B19-VALUE(MID(base_year,3,4)) -> 0 | C20: =C19-VALUE(MID(base_year,3,4)) -> 1 | D20: =D19-VALUE(MID(base_year,3,4)) -> 2 | E20: =E19-VALUE(MID(base_year,3,4)) -> 3 | F20: =F19-VALUE(MID(base_year,3,4)) -> 4 | G20: =G19-VALUE(MID(base_year,3,4)) -> 5 | H20: base FY from Assumptions!base_year
A21: Mid-year period t = n − 0.5 | C21: =C20-0.5 -> 0.5 | D21: =D20-0.5 -> 1.5 | E21: =E20-0.5 -> 2.5 | F21: =F20-0.5 -> 3.5 | G21: =G20-0.5 -> 4.5
A22: Discount factor 1 / (1+WACC)^t | C22: =1/(1+wacc_calc)^C21 -> 0.95681733 | D22: =1/(1+wacc_calc)^D21 -> 0.8759657 | E22: =1/(1+wacc_calc)^E21 -> 0.80194607 | F22: =1/(1+wacc_calc)^F21 -> 0.73418115 | G22: =1/(1+wacc_calc)^G21 -> 0.67214241
A23: PV of FCFF | C23: =C13*C22 -> 896058.45 | D23: =D13*D22 -> 879516.44 | E23: =E13*E22 -> 857141.15 | F23: =F13*F22 -> 827506.24 | G23: =G13*G22 -> 791337.91
A25: Terminal value & equity bridge | B25: Perpetuity (Gordon) | C25: Exit multiple | H25: Convention
A26: Terminal value (undiscounted) | B26: =G13*(1+tg)/(wacc_calc-tg) -> 17931205 | C26: =G14*exit_mult -> 15850735 | H26: Perp: FCFF_FY31×(1+g)/(WACC−g). Exit: EBITDA_FY31 × exit multiple
A27: Discount period for TV (years) | B27: =G21 -> 4.5 | C27: =G20 -> 5 | H27: Perp discounted at t=4.5 (mid-year consistent); Exit discounted at t=5.0 (end of FY31)
A28: PV of terminal value | B28: =B26/(1+wacc_calc)^B27 -> 12052323 | C28: =C26/(1+wacc_calc)^C27 -> 10193885
A29: Sum of PV FCFF (FY27 to FY31) | B29: =SUM(C23:G23) -> 4251560.2 | C29: =SUM(C23:G23) -> 4251560.2
A30: Enterprise value | B30: =B29+B28 -> 16303883 | C30: =C29+C28 -> 14445446
A31: + Cash | B31: =cash -> 1570421 | C31: =cash -> 1570421 | H31: Assumptions!cash: Jun 30 balance sheet 1,602,589 less 32,168 repurchased to Jul 9 (10-Q subsequent events)
A32: − Debt | B32: =debt -> 0 | C32: =debt -> 0 | H32: Assumptions!debt (0); leases excluded
A33: Equity value | B33: =B30+B31-B32 -> 17874304 | C33: =C30+C31-C32 -> 16015867
A34: Diluted shares (count) | B34: =shares -> 136710227 | C34: =shares -> 136710227 | H34: Assumptions!shares_diluted_current
A35: Implied price per share ($) = equity ×1000 / shares | B35: =B33*1000/B34 -> 130.74592 | C35: =C33*1000/C34 -> 117.15193
A36: Current share price ($) | B36: =price -> 80.23 | C36: =price -> 80.23 | H36: Assumptions!price
A37: Upside / (downside) vs current | B37: =B35/B36-1 -> 0.62963879 | C37: =C35/C36-1 -> 0.46020101
A38: PV TV as % of EV | B38: =B28/B30 -> 0.73923021 | C38: =C28/C30 -> 0.70568162
A40: Market-implied EBIT margin at current price | B40: Value | H40: Convention
A41: Price at probe margin lo ($) | B41: =(SUMPRODUCT(implied_margin_probe_lo*$C$4:$G$4*(1-tax)+$C$9:$G$9-$C$10:$G$10-$C$12:$G$12,1/(1+wacc_calc)^$C$21:$G$21)+(implied_margin_probe_lo*$G$4*(1-tax)+$G$9-$G$10-$G$12)*(1+tg)/(wacc_calc-tg)/(1+wacc_calc)^$G$21+cash-debt)/shares*1000 -> 76.639045 | H41: Same SUMPRODUCT repricing as the Sensitivity grids with the margin swapped in; probe margins are Assumptions inputs
A42: Price at probe margin hi ($) | B42: =(SUMPRODUCT(implied_margin_probe_hi*$C$4:$G$4*(1-tax)+$C$9:$G$9-$C$10:$G$10-$C$12:$G$12,1/(1+wacc_calc)^$C$21:$G$21)+(implied_margin_probe_hi*$G$4*(1-tax)+$G$9-$G$10-$G$12)*(1+tg)/(wacc_calc-tg)/(1+wacc_calc)^$G$21+cash-debt)/shares*1000 -> 88.029966
A43: Market-implied EBIT margin at current price | B43: =implied_margin_probe_lo+(price-B41)*(implied_margin_probe_hi-implied_margin_probe_lo)/(B42-B41) -> 0.12630494 | H43: Value per share is linear in margin, so linear interpolation between the two probes is exact; the check row below reprices at this margin and must return the current price
A45: Terminal reinvestment sensitivity | B45: Value | H45: Convention
...

Sheet Sensitivity
A1: Sensitivity: live formula grids. Each cell re-prices the DCF for the row WACC and the column g / exit multiple, using the DCF FCFF and EBITDA rows, the DCF t and n rows, and the defined names cash, debt, shares.
A2: Axes are centered on the base case (wacc_calc, tg, exit_mult) ± 2 steps; steps are Assumptions inputs sens_wacc_step / sens_g_step / sens_mult_step. The highlighted center cell must equal the DCF price.
A4: Grid 1: implied price ($), perpetuity method. WACC (rows) × terminal growth g (columns)
A5: rows: WACC = wacc_calc ± 2 × sens_wacc_step | columns: g = tg ± 2 × sens_g_step
B6: WACC ↓ / → | C6: =tg-2*sens_g_step -> 0.015 | D6: =tg-sens_g_step -> 0.02 | E6: =tg -> 0.025 | F6: =tg+sens_g_step -> 0.03 | G6: =tg+2*sens_g_step -> 0.035
B7: =wacc_calc-2*sens_wacc_step -> 0.0823 | C7: =(SUMPRODUCT(DCF!$C$13:$G$13,1/(1+$B7)^DCF!$C$21:$G$21)+DCF!$G$13*(1+C$6)/($B7-C$6)/(1+$B7)^DCF!$G$21+cash-debt)/shares*1000 -> 134.28274 | D7: =(SUMPRODUCT(DCF!$C$13:$G$13,1/(1+$B7)^DCF!$C$21:$G$21)+DCF!$G$13*(1+D$6)/($B7-D$6)/(1+$B7)^DCF!$G$21+cash-debt)/shares*1000 -> 142.06937 | E7: =(SUMPRODUCT(DCF!$C$13:$G$13,1/(1+$B7)^DCF!$C$21:$G$21)+DCF!$G$13*(1+E$6)/($B7-E$6)/(1+$B7)^DCF!$G$21+cash-debt)/shares*1000 -> 151.21493 | F7: =(SUMPRODUCT(DCF!$C$13:$G$13,1/(1+$B7)^DCF!$C$21:$G$21)+DCF!$G$13*(1+F$6)/($B7-F$6)/(1+$B7)^DCF!$G$21+cash-debt)/shares*1000 -> 162.10916 | G7: =(SUMPRODUCT(DCF!$C$13:$G$13,1/(1+$B7)^DCF!$C$21:$G$21)+DCF!$G$13*(1+G$6)/($B7-G$6)/(1+$B7)^DCF!$G$21+cash-debt)/shares*1000 -> 175.30661
B8: =wacc_calc-sens_wacc_step -> 0.0873 | C8: =(SUMPRODUCT(DCF!$C$13:$G$13,1/(1+$B8)^DCF!$C$21:$G$21)+DCF!$G$13*(1+C$6)/($B8-C$6)/(1+$B8)^DCF!$G$21+cash-debt)/shares*1000 -> 125.89424 | D8: =(SUMPRODUCT(DCF!$C$13:$G$13,1/(1+$B8)^DCF!$C$21:$G$21)+DCF!$G$13*(1+D$6)/($B8-D$6)/(1+$B8)^DCF!$G$21+cash-debt)/shares*1000 -> 132.49651 | E8: =(SUMPRODUCT(DCF!$C$13:$G$13,1/(1+$B8)^DCF!$C$21:$G$21)+DCF!$G$13*(1+E$6)/($B8-E$6)/(1+$B8)^DCF!$G$21+cash-debt)/shares*1000 -> 140.15854 | F8: =(SUMPRODUCT(DCF!$C$13:$G$13,1/(1+$B8)^DCF!$C$21:$G$21)+DCF!$G$13*(1+F$6)/($B8-F$6)/(1+$B8)^DCF!$G$21+cash-debt)/shares*1000 -> 149.15774 | G8: =(SUMPRODUCT(DCF!$C$13:$G$13,1/(1+$B8)^DCF!$C$21:$G$21)+DCF!$G$13*(1+G$6)/($B8-G$6)/(1+$B8)^DCF!$G$21+cash-debt)/shares*1000 -> 159.87764
B9: =wacc_calc -> 0.0923 | C9: =(SUMPRODUCT(DCF!$C$13:$G$13,1/(1+$B9)^DCF!$C$21:$G$21)+DCF!$G$13*(1+C$6)/($B9-C$6)/(1+$B9)^DCF!$G$21+cash-debt)/shares*1000 -> 118.59223 | D9: =(SUMPRODUCT(DCF!$C$13:$G$13,1/(1+$B9)^DCF!$C$21:$G$21)+DCF!$G$13*(1+D$6)/($B9-D$6)/(1+$B9)^DCF!$G$21+cash-debt)/shares*1000 -> 124.24882 | E9: =(SUMPRODUCT(DCF!$C$13:$G$13,1/(1+$B9)^DCF!$C$21:$G$21)+DCF!$G$13*(1+E$6)/($B9-E$6)/(1+$B9)^DCF!$G$21+cash-debt)/shares*1000 -> 130.74592 | F9: =(SUMPRODUCT(DCF!$C$13:$G$13,1/(1+$B9)^DCF!$C$21:$G$21)+DCF!$G$13*(1+F$6)/($B9-F$6)/(1+$B9)^DCF!$G$21+cash-debt)/shares*1000 -> 138.28589 | G9: =(SUMPRODUCT(DCF!$C$13:$G$13,1/(1+$B9)^DCF!$C$21:$G$21)+DCF!$G$13*(1+G$6)/($B9-G$6)/(1+$B9)^DCF!$G$21+cash-debt)/shares*1000 -> 147.14174
B10: =wacc_calc+sens_wacc_step -> 0.0973 | C10: =(SUMPRODUCT(DCF!$C$13:$G$13,1/(1+$B10)^DCF!$C$21:$G$21)+DCF!$G$13*(1+C$6)/($B10-C$6)/(1+$B10)^DCF!$G$21+cash-debt)/shares*1000 -> 112.17865 | D10: =(SUMPRODUCT(DCF!$C$13:$G$13,1/(1+$B10)^DCF!$C$21:$G$21)+DCF!$G$13*(1+D$6)/($B10-D$6)/(1+$B10)^DCF!$G$21+cash-debt)/shares*1000 -> 117.06913 | E10: =(SUMPRODUCT(DCF!$C$13:$G$13,1/(1+$B10)^DCF!$C$21:$G$21)+DCF!$G$13*(1+E$6)/($B10-E$6)/(1+$B10)^DCF!$G$21+cash-debt)/shares*1000 -> 122.63602 | F10: =(SUMPRODUCT(DCF!$C$13:$G$13,1/(1+$B10)^DCF!$C$21:$G$21)+DCF!$G$13*(1+F$6)/($B10-F$6)/(1+$B10)^DCF!$G$21+cash-debt)/shares*1000 -> 129.03009 | G10: =(SUMPRODUCT(DCF!$C$13:$G$13,1/(1+$B10)^DCF!$C$21:$G$21)+DCF!$G$13*(1+G$6)/($B10-G$6)/(1+$B10)^DCF!$G$21+cash-debt)/shares*1000 -> 136.4505
B11: =wacc_calc+2*sens_wacc_step -> 0.1023 | C11: =(SUMPRODUCT(DCF!$C$13:$G$13,1/(1+$B11)^DCF!$C$21:$G$21)+DCF!$G$13*(1+C$6)/($B11-C$6)/(1+$B11)^DCF!$G$21+cash-debt)/shares*1000 -> 106.50082 | D11: =(SUMPRODUCT(DCF!$C$13:$G$13,1/(1+$B11)^DCF!$C$21:$G$21)+DCF!$G$13*(1+D$6)/($B11-D$6)/(1+$B11)^DCF!$G$21+cash-debt)/shares*1000 -> 110.76275 | E11: =(SUMPRODUCT(DCF!$C$13:$G$13,1/(1+$B11)^DCF!$C$21:$G$21)+DCF!$G$13*(1+E$6)/($B11-E$6)/(1+$B11)^DCF!$G$21+cash-debt)/shares*1000 -> 115.57602 | F11: =(SUMPRODUCT(DCF!$C$13:$G$13,1/(1+$B11)^DCF!$C$21:$G$21)+DCF!$G$13*(1+F$6)/($B11-F$6)/(1+$B11)^DCF!$G$21+cash-debt)/shares*1000 -> 121.05504 | G11: =(SUMPRODUCT(DCF!$C$13:$G$13,1/(1+$B11)^DCF!$C$21:$G$21)+DCF!$G$13*(1+G$6)/($B11-G$6)/(1+$B11)^DCF!$G$21+cash-debt)/shares*1000 -> 127.34817
A13: Check: center cell − DCF price_perp (must be 0) | B13: =E9-price_perp -> 0 | C13: =IF(ABS(B13)<0.000001,"PASS","FAIL") -> PASS
A15: Grid 2: implied price ($), exit-multiple method. WACC (rows) × EV/EBITDA exit multiple (columns)
A16: rows: WACC = wacc_calc ± 2 × sens_wacc_step | columns: multiple = exit_mult ± 2 × sens_mult_step
B17: WACC ↓ / → | C17: =exit_mult-2*sens_mult_step -> 8.5 | D17: =exit_mult-sens_mult_step -> 9 | E17: =exit_mult -> 9.5 | F17: =exit_mult+sens_mult_step -> 10 | G17: =exit_mult+2*sens_mult_step -> 10.5
B18: =wacc_calc-2*sens_wacc_step -> 0.0823 | C18: =(SUMPRODUCT(DCF!$C$13:$G$13,1/(1+$B18)^DCF!$C$21:$G$21)+DCF!$G$14*C$17/(1+$B18)^DCF!$G$20+cash-debt)/shares*1000 -> 113.15059 | D18: =(SUMPRODUCT(DCF!$C$13:$G$13,1/(1+$B18)^DCF!$C$21:$G$21)+DCF!$G$14*D$17/(1+$B18)^DCF!$G$20+cash-debt)/shares*1000 -> 117.25978 | E18: =(SUMPRODUCT(DCF!$C$13:$G$13,1/(1+$B18)^DCF!$C$21:$G$21)+DCF!$G$14*E$17/(1+$B18)^DCF!$G$20+cash-debt)/shares*1000 -> 121.36897 | F18: =(SUMPRODUCT(DCF!$C$13:$G$13,1/(1+$B18)^DCF!$C$21:$G$21)+DCF!$G$14*F$17/(1+$B18)^DCF!$G$20+cash-debt)/shares*1000 -> 125.47816 | G18: =(SUMPRODUCT(DCF!$C$13:$G$13,1/(1+$B18)^DCF!$C$21:$G$21)+DCF!$G$14*G$17/(1+$B18)^DCF!$G$20+cash-debt)/shares*1000 -> 129.58736
B19: =wacc_calc-sens_wacc_step -> 0.0873 | C19: =(SUMPRODUCT(DCF!$C$13:$G$13,1/(1+$B19)^DCF!$C$21:$G$21)+DCF!$G$14*C$17/(1+$B19)^DCF!$G$20+cash-debt)/shares*1000 -> 111.20163 | D19: =(SUMPRODUCT(DCF!$C$13:$G$13,1/(1+$B19)^DCF!$C$21:$G$21)+DCF!$G$14*D$17/(1+$B19)^DCF!$G$20+cash-debt)/shares*1000 -> 115.2172 | E19: =(SUMPRODUCT(DCF!$C$13:$G$13,1/(1+$B19)^DCF!$C$21:$G$21)+DCF!$G$14*E$17/(1+$B19)^DCF!$G$20+cash-debt)/shares*1000 -> 119.23278 | F19: =(SUMPRODUCT(DCF!$C$13:$G$13,1/(1+$B19)^DCF!$C$21:$G$21)+DCF!$G$14*F$17/(1+$B19)^DCF!$G$20+cash-debt)/shares*1000 -> 123.24836 | G19: =(SUMPRODUCT(DCF!$C$13:$G$13,1/(1+$B19)^DCF!$C$21:$G$21)+DCF!$G$14*G$17/(1+$B19)^DCF!$G$20+cash-debt)/shares*1000 -> 127.26393
B20: =wacc_calc -> 0.0923 | C20: =(SUMPRODUCT(DCF!$C$13:$G$13,1/(1+$B20)^DCF!$C$21:$G$21)+DCF!$G$14*C$17/(1+$B20)^DCF!$G$20+cash-debt)/shares*1000 -> 109.30291 | D20: =(SUMPRODUCT(DCF!$C$13:$G$13,1/(1+$B20)^DCF!$C$21:$G$21)+DCF!$G$14*D$17/(1+$B20)^DCF!$G$20+cash-debt)/shares*1000 -> 113.22742 | E20: =(SUMPRODUCT(DCF!$C$13:$G$13,1/(1+$B20)^DCF!$C$21:$G$21)+DCF!$G$14*E$17/(1+$B20)^DCF!$G$20+cash-debt)/shares*1000 -> 117.15193 | F20: =(SUMPRODUCT(DCF!$C$13:$G$13,1/(1+$B20)^DCF!$C$21:$G$21)+DCF!$G$14*F$17/(1+$B20)^DCF!$G$20+cash-debt)/shares*1000 -> 121.07643 | G20: =(SUMPRODUCT(DCF!$C$13:$G$13,1/(1+$B20)^DCF!$C$21:$G$21)+DCF!$G$14*G$17/(1+$B20)^DCF!$G$20+cash-debt)/shares*1000 -> 125.00094
B21: =wacc_calc+sens_wacc_step -> 0.0973 | C21: =(SUMPRODUCT(DCF!$C$13:$G$13,1/(1+$B21)^DCF!$C$21:$G$21)+DCF!$G$14*C$17/(1+$B21)^DCF!$G$20+cash-debt)/shares*1000 -> 107.4529 | D21: =(SUMPRODUCT(DCF!$C$13:$G$13,1/(1+$B21)^DCF!$C$21:$G$21)+DCF!$G$14*D$17/(1+$B21)^DCF!$G$20+cash-debt)/shares*1000 -> 111.2888 | E21: =(SUMPRODUCT(DCF!$C$13:$G$13,1/(1+$B21)^DCF!$C$21:$G$21)+DCF!$G$14*E$17/(1+$B21)^DCF!$G$20+cash-debt)/shares*1000 -> 115.12471 | F21: =(SUMPRODUCT(DCF!$C$13:$G$13,1/(1+$B21)^DCF!$C$21:$G$21)+DCF!$G$14*F$17/(1+$B21)^DCF!$G$20+cash-debt)/shares*1000 -> 118.96062 | G21: =(SUMPRODUCT(DCF!$C$13:$G$13,1/(1+$B21)^DCF!$C$21:$G$21)+DCF!$G$14*G$17/(1+$B21)^DCF!$G$20+cash-debt)/shares*1000 -> 122.79652
B22: =wacc_calc+2*sens_wacc_step -> 0.1023 | C22: =(SUMPRODUCT(DCF!$C$13:$G$13,1/(1+$B22)^DCF!$C$21:$G$21)+DCF!$G$14*C$17/(1+$B22)^DCF!$G$20+cash-debt)/shares*1000 -> 105.6501 | D22: =(SUMPRODUCT(DCF!$C$13:$G$13,1/(1+$B22)^DCF!$C$21:$G$21)+DCF!$G$14*D$17/(1+$B22)^DCF!$G$20+cash-debt)/shares*1000 -> 109.39979 | E22: =(SUMPRODUCT(DCF!$C$13:$G$13,1/(1+$B22)^DCF!$C$21:$G$21)+DCF!$G$14*E$17/(1+$B22)^DCF!$G$20+cash-debt)/shares*1000 -> 113.14948 | F22: =(SUMPRODUCT(DCF!$C$13:$G$13,1/(1+$B22)^DCF!$C$21:$G$21)+DCF!$G$14*F$17/(1+$B22)^DCF!$G$20+cash-debt)/shares*1000 -> 116.89918 | G22: =(SUMPRODUCT(DCF!$C$13:$G$13,1/(1+$B22)^DCF!$C$21:$G$21)+DCF!$G$14*G$17/(1+$B22)^DCF!$G$20+cash-debt)/shares*1000 -> 120.64887
A24: Check: center cell − DCF price_exit (must be 0) | B24: =E20-price_exit -> 0 | C24: =IF(ABS(B24)<0.000001,"PASS","FAIL") -> PASS

Sheet Comps
A1: Comps: EV / LTM EBITDA (blue inputs from stockanalysis.com and GuruFocus), DECK implied value from peer multiples, football field
A3: Ticker | B3: EV / LTM EBITDA | C3: Source
A4: CROX | B4: 7.72 | C4: stockanalysis.com / GuruFocus, retrieved Sep 2026
A5: BIRK | B5: 9.5 | C5: stockanalysis.com 9.50x vs TipRanks 18.46x. Kept: yfinance same-currency recompute 8.89x (EUR items at EURUSD 1.1465, 2026-09-22) is within 15% of 9.50x
A6: NKE | B6: 11.35 | C6: stockanalysis.com, retrieved Sep 2026
A7: WWW | B7: 11.42 | C7: GuruFocus, retrieved Sep 2026
A8: SHOO | B8: 12.54 | C8: stockanalysis.com, retrieved Sep 2026
A9: ONON | B9: 15.71 | C9: stockanalysis.com, retrieved Sep 2026
A11: Minimum | B11: =MIN(B4:B9) -> 7.72
A12: 25th percentile | B12: =QUARTILE(B4:B9,1) -> 9.9625
A13: Median | B13: =MEDIAN(B4:B9) -> 11.385
A14: 75th percentile | B14: =QUARTILE(B4:B9,3) -> 12.26
A15: Maximum | B15: =MAX(B4:B9) -> 15.71
A17: DECK implied value from peer EV / LTM EBITDA multiples
A18: ($ thousands unless stated) | B18: 25th percentile | C18: Median | D18: 75th percentile | E18: Source / formula
A19: Peer EV / LTM EBITDA (x) | B19: =B12 -> 9.9625 | C19: =B13 -> 11.385 | D19: =B14 -> 12.26 | E19: peer statistics above
A20: DECK LTM EBITDA to Jun 30 2026 | B20: =ltm_ebitda -> 1326979 | C20: =ltm_ebitda -> 1326979 | D20: =ltm_ebitda -> 1326979 | E20: Historical!ltm_ebitda = FY2026 + Q1 FY2027 - Q1 FY2026 (income from operations + D&A and accretion)
A21: Implied enterprise value | B21: =B19*B20 -> 13220028 | C21: =C19*C20 -> 15107656 | D21: =D19*D20 -> 16268763 | E21: peer multiple x DECK LTM EBITDA
A22: + Cash | B22: =cash -> 1570421 | C22: =cash -> 1570421 | D22: =cash -> 1570421 | E22: Assumptions!cash: Jun 30 balance sheet 1,602,589 less 32,168 repurchased to Jul 9 (10-Q subsequent events)
A23: - Debt | B23: =debt -> 0 | C23: =debt -> 0 | D23: =debt -> 0 | E23: Assumptions!debt (0); leases excluded, same bridge as DCF
A24: Implied equity value | B24: =B21+B22-B23 -> 14790449 | C24: =C21+C22-C23 -> 16678077 | D24: =D21+D22-D23 -> 17839184 | E24: EV + cash - debt
A25: Diluted shares (count) | B25: =shares -> 136710227 | C25: =shares -> 136710227 | D25: =shares -> 136710227 | E25: Assumptions!shares_diluted_current
A26: Implied price per share ($) | B26: =B24*1000/B25 -> 108.18832 | C26: =C24*1000/C25 -> 121.99582 | D26: =D24*1000/D25 -> 130.48902 | E26: equity x 1000 / shares
A28: DECK current EV / LTM EBITDA (x) | B28: =(price*shares/1000+debt-cash)/ltm_ebitda -> 7.0821321 | E28: context: (price x shares / 1000 + debt - cash) / LTM EBITDA, at Assumptions!price
A29: Median ex-IFRS peers (CROX, NKE, WWW, SHOO) | B29: =MEDIAN(B4,B6,B7,B8) -> 11.385 | E29: US GAAP reporters only; BIRK (EUR, IFRS) and ONON (CHF, IFRS) excluded
A30: Value per share at DECK's current EV / LTM EBITDA multiple ($) | B30: =(SUMPRODUCT(DCF!$C$13:$G$13,1/(1+wacc_calc)^DCF!$C$21:$G$21)+DCF!$G$14*$B$28/(1+wacc_calc)^DCF!$G$20+cash-debt)/shares*1000 -> 98.174046 | E30: DCF exit-multiple method with the market's current multiple in place of exit_mult
A31: DECK EV / EBITDA per stockanalysis (x) | B31: 7.39 | E31: stockanalysis.com, Sep 21 2026
A32: DECK EV / EBITDA per GuruFocus (x) | B32: 7.62 | E32: GuruFocus, Sep 1 2026
A33: DECK 10-year median EV / EBITDA per GuruFocus (x) | B33: 13.49 | E33: GuruFocus, Sep 1 2026
A35: Football field ($ per share): low and high per bar
A36: Bar | B36: Low | C36: High | D36: Source / formula
A37: DCF perpetuity (WACC +/-1 step, g +/-1 step) | B37: =MIN(Sensitivity!$D$8:$F$10) -> 117.06913 | C37: =MAX(Sensitivity!$D$8:$F$10) -> 149.15774 | D37: MIN / MAX of Sensitivity grid 1 inner 3x3, Sensitivity!$D$8:$F$10
A38: DCF exit multiple (WACC +/-1 step, multiple +/-1 step) | B38: =MIN(Sensitivity!$D$19:$F$21) -> 111.2888 | C38: =MAX(Sensitivity!$D$19:$F$21) -> 123.24836 | D38: MIN / MAX of Sensitivity grid 2 inner 3x3, Sensitivity!$D$19:$F$21
A39: Monte Carlo P10 to P90 | B39: =MC!B10 -> 111.5651 | C39: =MC!B14 -> 144.29901 | D39: MC tab (mc/mc_summary.csv, seed per Assumptions!mc_seed)
A40: Trading comps (25th to 75th percentile peer multiple) | B40: =B26 -> 108.18832 | C40: =D26 -> 130.48902 | D40: implied price per share, this tab
A41: Analyst price targets | B41: 70 | C41: 184 | D41: stockanalysis.com, Sep 2026, 27 analysts
A42: 52-week range | B42: 77.36 | C42: 122.29 | D42: stockanalysis.com, Sep 2026
A44: Base DCF price, perpetuity ($) | B44: =price_perp -> 130.74592 | D44: DCF!price_perp
A45: Current price ($) | B45: =price -> 80.23 | D45: Assumptions!price

Sheet MC
A1: Monte Carlo: perpetuity-method value per share. Written by mc/deck_mc.py (blue = values from mc_summary.csv).
A3: metric | B3: value | C3: source
A4: Distribution (value per share, $)
A5: runs | B5: 10000 | C5: mc/mc_summary.csv, Python output, seed 42
A6: seed | B6: 42 | C6: mc/mc_summary.csv, Python output, seed 42
A7: mean | B7: 127.33473 | C7: mc/mc_summary.csv, Python output, seed 42
A8: std | B8: 12.896178 | C8: mc/mc_summary.csv, Python output, seed 42
A9: P5 | B9: 107.89591 | C9: mc/mc_summary.csv, Python output, seed 42
A10: P10 | B10: 111.5651 | C10: mc/mc_summary.csv, Python output, seed 42
A11: P25 | B11: 118.17046 | C11: mc/mc_summary.csv, Python output, seed 42
A12: P50 | B12: 126.40326 | C12: mc/mc_summary.csv, Python output, seed 42
A13: P75 | B13: 135.5098 | C13: mc/mc_summary.csv, Python output, seed 42
A14: P90 | B14: 144.29901 | C14: mc/mc_summary.csv, Python output, seed 42
A15: P95 | B15: 150.29753 | C15: mc/mc_summary.csv, Python output, seed 42
A16: min | B16: 90.407313 | C16: mc/mc_summary.csv, Python output, seed 42
... A22: current_price | B22: 80.23 | C22: mc/mc_summary.csv, Python output, seed 42
A24: Guardrail: WACC - g >= mc_guardrail_wacc_minus_g_min
A25: guardrail_runs_violating_initially | B25: 0 | C25: mc/mc_summary.csv, Python output, seed 42
A26: guardrail_total_redraws | B26: 0 | C26: mc/mc_summary.csv, Python output, seed 42
A27: guardrail_redraw_passes | B27: 0 | C27: mc/mc_summary.csv, Python output, seed 42
A29: Tornado: Spearman rank correlation of driver draw vs value
A30: spearman_WACC | B30: -0.625541 | C30: mc/mc_summary.csv, Python output, seed 42
A31: spearman_EBIT margin | B31: 0.54072 | C31: mc/mc_summary.csv, Python output, seed 42
A32: spearman_Revenue growth shift | B32: 0.400745 | C32: mc/mc_summary.csv, Python output, seed 42
A33: spearman_Terminal growth g | B33: 0.311406 | C33: mc/mc_summary.csv, Python output, seed 42
A35: Deterministic reconciliation (all drivers at mode)
A36: deterministic_python | B36: 130.74592 | C36: mc/mc_summary.csv, Python output, seed 42
A37: deterministic_excel_price_perp | B37: 130.74592 | C37: mc/mc_summary.csv, Python output, seed 42
A38: deterministic_diff | B38: 0 | C38: mc/mc_summary.csv, Python output, seed 42
A39: wacc_capm_reference | B39: 0.0923 | C39: mc/mc_summary.csv, Python output, seed 42
A41: Live check
A42: price_perp (live link to DCF) | B42: =price_perp -> 130.74592
A43: |deterministic_python - live price_perp| < $0.005 | B43: =ABS(B36-B42) -> 2.8421709e-14 | C43: =IF(B43<0.005,"PASS","FAIL") -> PASS
A44: |MC current_price - Assumptions price| < $0.005 | B44: =ABS(B22-price) -> 0 | C44: =IF(B44<0.005,"PASS","FAIL") -> PASS
